<?xml version="1.0"?>
<robot xmlns:xacro="http://www.ros.org/wiki/xacro">
<xacro:property name="pi" value="3.1415926535897931" />
<!--definition of default_inertial -->
<xacro:macro name="T_module_4th" params="parent name *origin">

<!-- joint between base_link and Lockring_Link -->
  <joint name="${name}_joint_0" type="fixed" >
    <insert_block name="origin" />
    <parent link="${parent}" />
    <child link="${name}_Lr_Link_0" />
  </joint>

<!--the Lockring_Link in T module-->
  <link name="${name}_Lr_Link_0">
    <inertial>
      <origin xyz="-0.0062199 -4.712E-05 0.11151" rpy="0 0 0" />
      <mass   value="0.5" />
      <inertia  ixx="0.0043213"
        ixy="-5.1881E-07"
        ixz="0.00020387"
        iyy="0.0045007"
        iyz="4.834E-07"
        izz="0.0020727" />
      </inertial>
    <visual>
      <origin xyz="0 0 0" rpy="0 0 0" />
      <geometry>
        <mesh filename="package://mr_description/meshes/VT_InLink_4th.STL" />
      </geometry>
      <material name="White"/>
    </visual>
<!--    <collision>-->
<!--      <origin xyz="0 0 0" rpy="0 0 0" />-->
<!--      <geometry>-->
<!--        <mesh filename="package://mr_description/meshes/VT_InLink_4th.STL" />-->
<!--      </geometry>-->
<!--    </collision>-->
  </link>

<!-- joint between Lockring_Link and TModule_InLink -->
    <joint name="${name}_Lr_Joint_1" type="fixed">
      <origin xyz="0 0 0.1105" rpy="1.5708 0 0" />
      <parent link="${name}_Lr_Link_0" />
      <child  link="${name}_InLink_1" />
      <axis   xyz="0 0 0" />
      <limit  lower="0" upper="0"  effort="0"   velocity="0" />
    </joint>

<!--the TModule_InLink in T module-->
  <link name="${name}_InLink_1">
    <inertial>
      <origin xyz="0.014606 -0.023405 6.7266E-05" rpy="0 0 0" />
      <mass   value="1.2" />
      <inertia   ixx="0.0016912"
        ixy="-8.2481E-05"
        ixz="-1.3704E-06"
        iyy="0.00075608"
        iyz="-5.6454E-07"
        izz="0.0014025" />
    </inertial>
    <visual>
      <origin   xyz="0 0 0"  rpy="0 0 0" />
      <geometry>
        <mesh   filename="package://mr_description/meshes/T_InLink_4th.STL" />
      </geometry>
      <material name="Red"/>
    </visual>
    <collision>
	<origin   xyz="0 0 0"  rpy="0 0 0" />    
<!--      <origin   xyz="0 0 0"  rpy="0 0 0" />-->
      <geometry>
	<cylinder radius="0.05" length="0.07" />        
<!--        <mesh   filename="package://mr_description/meshes/T_InLink_4th.STL" />-->
      </geometry>
    </collision>
  </link>
  <!--the IModule_InLink Gazebo tag-->
  <gazebo reference="${name}_InLink_1">
    <material>Gazebo/Red</material>
  </gazebo>

<!-- joint between TModule_InLink and TModule_OutLink -->
  <joint  name="${name}_Joint"  type="revolute">
<!--  <joint  name="${name}_Joint"  type="continuous">-->
    <origin  xyz="-0.0145 0 0"  rpy="0 0 0" />
    <parent  link="${name}_InLink_1" />
    <child   link="${name}_OutLink_2" />
    <axis   xyz="-1 0 0" />
    <limit  lower="-2.07" upper="2.07"  effort="0"  velocity="0" />
    <dynamics damping="0.7"/>       
  </joint>
  
  <!--    test reduction ratio-->
  <transmission name="${name}_trans">
    <type>transmission_interface/SimpleTransmission</type>
    <joint name="${name}_Joint" >
      <hardwareInterface>PositionJointInterface</hardwareInterface>
      <hardwareInterface>VelocityJointInterface</hardwareInterface>
      <hardwareInterface>EffortJointInterface</hardwareInterface>
    </joint>
    <actuator name="${name}_motor">
      <mechanicalReduction>480</mechanicalReduction> 
      <hardwareInterface>PositionJointInterface</hardwareInterface>
      <hardwareInterface>VelocityJointInterface</hardwareInterface>
      <hardwareInterface>EffortJointInterface</hardwareInterface>
    </actuator>
  </transmission>


<!--the TModule_OutLink in T module-->
  <link  name="${name}_OutLink_2">
    <inertial>
      <origin xyz="-0.017304 0.030846 2.9874E-05" rpy="0 0 0" />
      <mass  value="1" />
      <inertia   ixx="0.0012074"
        ixy="-0.00030836"
        ixz="-2.8267E-07"
        iyy="0.00068337"
        iyz="-3.7727E-07"
        izz="0.0011522" />
    </inertial>
    <visual>
      <origin  xyz="0 0 0"  rpy="0 0 0" />
      <geometry>
        <mesh  filename="package://mr_description/meshes/T_OutLink_4th.STL" />
      </geometry>
      <material  name="Red"/>
    </visual>
    <collision>
          <origin  xyz="0 -0.025 0" rpy="${pi*0.5} 0 0" />
<!--      <origin  xyz="0 0 0" rpy="0 0 0" />-->
      <geometry>
      	<cylinder radius="0.05" length="0.12" />        
<!--        <mesh  filename="package://mr_description/meshes/T_OutLink_4th.STL" />-->
      </geometry>
    </collision>
  </link>
  <!--the IModule_InLink Gazebo tag-->
  <gazebo reference="${name}_OutLink_2">
    <material>Gazebo/Red</material>
  </gazebo>

<!-- joint between TModule_OutLink and Lockring_Link -->
    <joint name="${name}_Lr_Joint_3" type="fixed">
      <origin  xyz="0.015 0.0987 0"  rpy="-1.5708 0 0" />
      <parent link="${name}_OutLink_2" />
      <child  link="${name}_Link" />
      <axis   xyz="0 0 0" />
      <limit  lower="0" upper="0"  effort="0"   velocity="0" />
    </joint>

<!--the Lockring_Link in T module-->
  <link name="${name}_Link">
    <inertial>
      <origin xyz="-0.0067199 -4.712E-05 -0.097693" rpy="0 0 0" />
      <mass value="0.5" />
      <inertia ixx="0.0043213"
        ixy="-5.1881E-07"
        ixz="0.00020387"
        iyy="0.0045007"
        iyz="4.834E-07"
        izz="0.0020727" />
    </inertial>
    <visual>
      <origin  xyz="0 0 0"  rpy="0 0 0" />
      <geometry>
        <mesh  filename="package://mr_description/meshes/VT_OutLink_4th.STL" />
      </geometry>
      <material name="White"/>
    </visual>
<!--    <collision>-->
<!--      <origin  xyz="0 0 0" rpy="0 0 0" />-->
<!--      <geometry>-->
<!--        <mesh  filename="package://mr_description/meshes/VT_OutLink_4th.STL" />-->
<!--      </geometry>-->
<!--    </collision>   -->
  </link>




</xacro:macro>
</robot>
