<?xml version="1.0"?>
<robot xmlns:xacro="http://www.ros.org/wiki/xacro">


<!--definition of default_inertial -->
<xacro:macro name="I_module_4th" params="parent name *origin rotate_direction_pos:=1">

<!-- joint between base_link and Lockring_Link -->
	<joint name="${name}_joint_0" type="fixed" >
		<insert_block name="origin" />
		<parent link="${parent}" />
		<child link="${name}_Lr_Link_0" />
	</joint>

<!--the Lockring_Link in I module-->
  <link name="${name}_Lr_Link_0">
    <inertial>
      <origin xyz="0.00010582 -0.00010564 0.078074" rpy="0 0 0" />
      <mass value="0.5" />
      <inertia 
        ixx="0.0020854"
        ixy="1.8653E-06"
        ixz="3.8481E-07"
        iyy="0.002097"
        iyz="-3.6471E-07"
        izz="0.0010917" />
    </inertial>
    <visual>
      <origin xyz="0 0 0" rpy="0 0 0" />
      <geometry>
        <mesh filename="package://mr_description/meshes/VI_InLink_4th.STL" />
      </geometry>
      <material name="White"/>
    </visual>
<!--    <collision>-->
<!--      <origin xyz="0 0 0" rpy="0 0 0" />-->
<!--      <geometry>-->
<!--        <mesh filename="package://mr_description/meshes/VI_InLink_4th.STL" />-->
<!--      </geometry>-->
<!--    </collision>-->
  </link>

<!-- joint between Lockring_Link and IModule_InLink -->
    <joint name="${name}_Lr_Joint_1" type="fixed">
      <origin xyz="0 0 0" rpy="0 0 0" />
      <parent link="${name}_Lr_Link_0" />
      <child  link="${name}_InLink_1" />
      <axis   xyz="0 0 0" />
      <limit  lower="0" upper="0"  effort="0"   velocity="0" />
    </joint>

<!--the IModule_InLink in I module-->
  <link name="${name}_InLink_1">
    <inertial>
      <origin xyz="0.00017879 -0.00017813 0.047968" rpy="0 0 0" />
      <mass   value="1.2" />
      <inertia   
        ixx="0.00057835"
        ixy="1.8161E-06"
        ixz="-1.3137E-06"
        iyy="0.00058218"
        iyz="1.324E-06"
        izz="0.00066749"  />
    </inertial>
    <visual>
      <origin   xyz="0 0 0.1091"  rpy="0 ${0.5 * pi} 0" />
      <geometry>
        <mesh   filename="package://mr_description/meshes/I_InLink_4th.STL" />
      </geometry>
      <material name="Red"/>
    </visual>
    <collision>
<!--      <origin   xyz="0 0 0"  rpy="0 0 0" />-->
	<origin   xyz="0 0 0"  rpy="0 0 0" />
      <geometry>
<!--        <mesh   filename="package://mr_description/meshes/I_InLink_4th.STL" />-->
	<cylinder radius="0.05" length="0.158"  />
      </geometry>
    </collision>
  </link>
  <!--the IModule_InLink Gazebo tag-->
  <gazebo reference="${name}_InLink_1">
    <material>Gazebo/Red</material>
  </gazebo>

<!-- joint between IModule_InLink and IModule_OutLink -->
  <joint  name="${name}_Joint"  type="continuous">
    <origin  xyz="0 0 0.091" rpy="2.3579 1.5708 0" />
    <parent  link="${name}_InLink_1" />
    <child   link="${name}_OutLink_2" />

<!--    <xacro:if value="${rotate_direction_pos}">-->
<!--       <axis   xyz="0 0 1" />-->
<!--    </xacro:if>-->
<!--    <xacro:unless value="${rotate_direction_pos}">-->
<!--       <axis   xyz="0 0 -1" />-->
<!--    </xacro:unless>-->
    <axis   xyz="${-1 * rotate_direction_pos} 0 0 " />
    <dynamics damping="0.7"/>       
    <limit   effort="75"  velocity="1.1" />
  </joint>
  
  
  <!--    test reduction ratio-->
  <transmission name="${name}_trans">
    <type>transmission_interface/SimpleTransmission</type>
    <joint name="${name}_Joint">
      <hardwareInterface>PositionJointInterface</hardwareInterface>
      <hardwareInterface>VelocityJointInterface</hardwareInterface>
      <hardwareInterface>EffortJointInterface</hardwareInterface>      
    </joint>
    <actuator name="${name}_motor">
      <mechanicalReduction>457</mechanicalReduction>
      <hardwareInterface>PositionJointInterface</hardwareInterface>
      <hardwareInterface>VelocityJointInterface</hardwareInterface>
      <hardwareInterface>EffortJointInterface</hardwareInterface>
    </actuator>
  </transmission>

<!--the IModule_OutLink in I module-->
  <link  name="${name}_OutLink_2">
    <inertial>  
			<origin  xyz="-0.046419 2.0299E-06 3.8153E-07" rpy="0 0 0" />
      <mass    value="1" />
      <inertia 
        ixx="0.00030154"
        ixy="1.7546E-09"
        ixz="-9.4475E-10"
        iyy="0.00021262"
        iyz="-2.5116E-06"
        izz="0.0002126" />
    </inertial>
    <visual>
      <origin  xyz="0 0 0"  rpy="0 0 0" />
      <geometry>
        <mesh  filename="package://mr_description/meshes/I_OutLink_4th.STL" />
      </geometry>
      <material  name="Red"/>
    </visual>
<!--    <collision>-->
<!--      <origin  xyz="0 0 0" rpy="0 0 0" />-->
<!--      <geometry>-->
<!--        <mesh  filename="package://mr_description/meshes/I_OutLink_4th.STL" />-->
<!--      </geometry>-->
<!--    </collision>-->
  </link>
  <!--the IModule_OutLink Gazebo tag-->
  <gazebo reference="${name}_OutLink_2">
    <material>Gazebo/Red</material>
  </gazebo>

<!-- joint between IModule_OutLink and Lockring_Link -->
    <joint name="${name}_Lr_Joint_3" type="fixed">
      <origin xyz="-0.0685 0 0" rpy="-1.5708 0.78714 1.5708" />
      <parent link="${name}_OutLink_2" />
      <child  link="${name}_Link" />
      <axis   xyz="0 0 0" />
      <limit  lower="0" upper="0"  effort="0"   velocity="0" />
    </joint>

<!--the Lockring_Link in I module-->
  <link name="${name}_Link">
    <inertial>
      <origin  xyz="0.00010582 -0.00010564 -0.081426"  rpy="0 0 0" />
      <mass    value="0.5" />
      <inertia   ixx="0.0020854"
        ixy="1.8653E-06"
        ixz="3.8481E-07"
        iyy="0.002097"
        iyz="-3.6471E-07"
        izz="0.0010917" />
    </inertial>
    <visual>
      <origin  xyz="0 0 0"  rpy="0 0 0" />
      <geometry>
        <mesh  filename="package://mr_description/meshes/VI_OutLink_4th.STL" />
      </geometry>
      <material name="White"/>
    </visual>
<!--    <collision>-->
<!--      <origin  xyz="0 0 0" rpy="0 0 0" />-->
<!--      <geometry>-->
<!--        <mesh  filename="package://mr_description/meshes/VI_OutLink_4th.STL" />-->
<!--      </geometry>-->
<!--    </collision>-->
  </link>




</xacro:macro>
</robot>
